<?xml version="1.0"?>
<robot xmlns:xacro="http://www.ros.org/wiki/xacro"  name="komurin_2">

    <xacro:include filename="intertial_macros.xacro"/>

    <material name="mdf">
        <color rgba="0.36 0.282 0.168 1" />
    </material>

    <material name="wheel">
        <color rgba="0.071 0.57 0.71 1" />
    </material>
    
    <material name="mechanum">
        <color rgba="0.0 0.0 0.0 1" />
    </material>
    
    <link name="base_link">
    </link>

    <joint name="chassis_joint" type="fixed">
        <parent link="base_link" />
        <child link="chassis" />
        <origin xyz = "-0.095 0 0" />
    </joint>

    <link name="chassis">
        <visual>
            <origin xyz="0.1485 0 0.025" />
            <geometry>
                <box size="0.297 0.21 0.05" />
            </geometry>
            <material name="mdf" />
        </visual>
        <collision>
            <origin xyz="0.1485 0 0.025" />
            <geometry>
                <box size="0.297 0.21 0.05" />
            </geometry>
        </collision>
        <xacro:inertial_box mass="0.5" x="0.297" y="0.21" z="0.05">
            <origin xyz="0.1485 0 0.025" rpy="0 0 0"/>
        </xacro:inertial_box>
    </link>


    <joint name="left_wheel_joint" type="continuous">
        <parent link="base_link"/>
        <child link="left_wheel"/>
        <origin xyz="0 0.125 0" rpy="-${pi/2} 0 0"/>
        <axis xyz="0 0 1"/>
    </joint>

    <link name="left_wheel">
        <visual>
            <geometry>
                <cylinder radius="0.033" length="0.027" />
            </geometry>
            <material name="wheel"/>
        </visual>
        <collision>
            <geometry>
                <cylinder radius="0.033" length="0.027" />
            </geometry>
        </collision>
        <xacro:inertial_cylinder mass="0.1" length="0.04" radius="0.033">
            <origin xyz="0 0 0" rpy="0 0 0"/>
        </xacro:inertial_cylinder>
    </link>

    <joint name="right_wheel_joint" type="continuous">
        <parent link="base_link"/>
        <child link="right_wheel"/>
        <origin xyz="0 -0.125 0" rpy="${pi/2} 0 0"/>
        <axis xyz="0 0 -1"/>
    </joint>

    <link name="right_wheel">
        <visual>
            <geometry>
                <cylinder radius="0.033" length="0.027" />
            </geometry>
            <material name="wheel"/>
        </visual>
        <collision>
            <geometry>
                <cylinder radius="0.033" length="0.027" />
            </geometry>
        </collision>
        <xacro:inertial_cylinder mass="0.1" length="0.04" radius="0.033">
            <origin xyz="0 0 0" rpy="0 0 0"/>
        </xacro:inertial_cylinder>
    </link>

    <joint name="mechanum_wheel_joint" type="fixed">
        <parent link="chassis"/>
        <child link="mechanum_wheel"/>
        <origin xyz="0.26 0 0"/>
    </joint>

    <link name="mechanum_wheel">
        <visual>
            <geometry>
                <sphere radius="0.033"/>
            </geometry>
            <material name="mechanum"/>
        </visual>
        <collision>
            <geometry>
                <sphere radius="0.033"/>
            </geometry>
        </collision>
        <xacro:inertial_sphere mass="0.1" radius="0.033">
            <origin xyz="0 0 0" rpy="0 0 0"/>
        </xacro:inertial_sphere>
    </link>

</robot>